Workbook

Sheet README
A1: eToro Group Ltd (NASDAQ: ETOR): audit workbook
A2: Prepared 2026-09-29 by IG Finance (buy-side analysis). Companion to eToro_Competitive_Thesis_2026-09-29.docx. Confidential, for internal discussion.
A4: CONFLICT OF INTEREST: the requester works in IG Group Finance (IG Australia). IG Group is a direct competitor of eToro and is included in the peer set as a benchmark only. It is excluded from the growth-strategy matrix.
A6: Scope
A7: 1. Inputs: every disclosed figure as a hard-coded blue input, with source URL, source type and period.
A8: 2. Historical Build & Ratios: quarterly Q1 2024 to Q2 2026 and annual 2023 to 2025 plus LTM, all formulas. Growth, CAGR, margins, take-rate, NC per funded account, and a stated-vs-recomputed cross-check block (MATCH/FLAG).
A9: 3. Peer Benchmark: eToro vs the six confirmed peers (IG Group, Plus500, Webull, XTB, Trading 212, Swissquote). USD conversion, multiples and growth-adjusted multiples by formula. Also holds moat ratings (analyst inputs).
A10: 4. Valuation & Scenarios: eToro EV range (share-count x cash-credit cases), M&A cross-checks (IG/Freetrade, J. Safra Sarasin/Saxo, eToro/TradeZero), and bull/base/bear.
A11: 5. Audit Log: issues found in the source materials and in this build.
A12: 6. Buffett Scorecard: eight tests with live links to the build. Framed as one investor's published framework, not a claim about what Buffett would conclude.
A14: Limitations, stated plainly
A15: a) The network egress proxy blocked WebFetch for every domain tried (investors.etoro.com, sec.gov, globenewswire, wikipedia and others). Every figure comes from web-search summaries of the cited URLs, not from the primary documents. Each input is graded accordingly. Re-verify against the 20-F and 6-K filings before external use.
... A24: Recalculated with LibreOffice headless. Zero formula errors required before release.

Sheet Inputs
A1: Inputs: disclosed figures (blue). Source = URL summarised via WebSearch (WebFetch blocked). CO = company disclosure; PR = press; AGG = aggregator.
A3: ID | B3: Metric | C3: Value | D3: Unit | E3: Period | F3: Source URL | G3: Type | H3: Note
A4: eToro: quarterly (US$m unless stated)
A5: NC_Q1_24 | B5: Net contribution Q1 2024 | C5: 201 | D5: $m | E5: Q1_24 | F5: https://investors.etoro.com/news-releases/news-release-details/etoro-reports-first-quarter-2025-results | G5: CO
A6: NC_Q3_24 | B6: Net contribution Q3 2024 | C6: 167 | D6: $m | E6: Q3_24 | F6: https://www.nasdaq.com/press-release/etoro-reports-third-quarter-2025-results-2025-11-10 | G6: CO
A7: NC_Q4_24 | B7: Net contribution Q4 2024 | C7: 253 | D7: $m | E7: Q4_24 | F7: https://www.nasdaq.com/press-release/etoro-reports-fourth-quarter-and-full-year-2025-results-2026-02-17 | G7: CO
A8: NC_Q1_25 | B8: Net contribution Q1 2025 | C8: 217 | D8: $m | E8: Q1_25 | F8: https://investors.etoro.com/news-releases/news-release-details/etoro-reports-first-quarter-2025-results | G8: CO
A9: NC_Q2_25 | B9: Net contribution Q2 2025 | C9: 210 | D9: $m | E9: Q2_25 | F9: https://www.nasdaq.com/press-release/etoro-reports-second-quarter-2025-results-2025-08-12 | G9: CO
A10: NC_Q3_25 | B10: Net contribution Q3 2025 | C10: 215 | D10: $m | E10: Q3_25 | F10: https://www.nasdaq.com/press-release/etoro-reports-third-quarter-2025-results-2025-11-10 | G10: CO
A11: NC_Q4_25 | B11: Net contribution Q4 2025 | C11: 227 | D11: $m | E11: Q4_25 | F11: https://www.nasdaq.com/press-release/etoro-reports-fourth-quarter-and-full-year-2025-results-2026-02-17 | G11: CO
A12: NC_Q1_26 | B12: Net contribution Q1 2026 | C12: 258 | D12: $m | E12: Q1_26 | F12: https://www.etoro.com/en-us/news-and-analysis/latest-news/press-release/etoro-reports-q1-2026-results/ | G12: CO
A13: NC_Q2_26 | B13: Net contribution Q2 2026 | C13: 229 | D13: $m | E13: Q2_26 | F13: https://investors.etoro.com/news-releases/news-release-details/etoro-reports-second-quarter-2026-results | G13: CO
A14: EB_Q1_24 | B14: Adj. EBITDA Q1 2024 | C14: 87 | D14: $m | E14: Q1_24 | F14: https://investors.etoro.com/news-releases/news-release-details/etoro-reports-first-quarter-2025-results | G14: CO
A15: EB_Q2_24 | B15: Adj. EBITDA Q2 2024 | C15: 55 | D15: $m | E15: Q2_24 | F15: https://www.nasdaq.com/press-release/etoro-reports-second-quarter-2025-results-2025-08-12 | G15: CO
A16: EB_Q3_24 | B16: Adj. EBITDA Q3 2024 | C16: 55 | D16: $m | E16: Q3_24 | F16: https://www.nasdaq.com/press-release/etoro-reports-third-quarter-2025-results-2025-11-10 | G16: CO
... A27: NI_Q1_25 | B27: GAAP net income Q1 2025 | C27: 60 | D27: $m | E27: Q1_25 | F27: https://investors.etoro.com/news-releases/news-release-details/etoro-reports-first-quarter-2025-results | G27: CO
A28: NI_Q2_25 | B28: GAAP net income Q2 2025 | C28: 30.2 | D28: $m | E28: Q2_25 | F28: https://www.nasdaq.com/press-release/etoro-reports-second-quarter-2025-results-2025-08-12 | G28: CO | H28: Q2 25 includes $15m IPO costs
A29: NI_Q3_25 | B29: GAAP net income Q3 2025 | C29: 57 | D29: $m | E29: Q3_25 | F29: https://www.nasdaq.com/press-release/etoro-reports-third-quarter-2025-results-2025-11-10 | G29: CO
A30: NI_Q1_26 | B30: GAAP net income Q1 2026 | C30: 82 | D30: $m | E30: Q1_26 | F30: https://www.etoro.com/en-us/news-and-analysis/latest-news/press-release/etoro-reports-q1-2026-results/ | G30: CO
A31: NI_Q2_26 | B31: GAAP net income Q2 2026 | C31: 53 | D31: $m | E31: Q2_26 | F31: https://investors.etoro.com/news-releases/news-release-details/etoro-reports-second-quarter-2026-results | G31: CO
A32: FA_Q3_24 | B32: Funded accounts Q3 2024 | C32: 3.21 | D32: m | E32: Q3_24 | F32: https://investors.etoro.com/news-releases (quarterly results; via search summaries) | G32: CO
A33: FA_Q1_25 | B33: Funded accounts Q1 2025 | C33: 3.58 | D33: m | E33: Q1_25 | F33: https://investors.etoro.com/news-releases (quarterly results; via search summaries) | G33: CO
A34: FA_Q2_25 | B34: Funded accounts Q2 2025 | C34: 3.63 | D34: m | E34: Q2_25 | F34: https://investors.etoro.com/news-releases (quarterly results; via search summaries) | G34: CO
A35: FA_Q3_25 | B35: Funded accounts Q3 2025 | C35: 3.73 | D35: m | E35: Q3_25 | F35: https://investors.etoro.com/news-releases (quarterly results; via search summaries) | G35: CO
A36: FA_Q4_25 | B36: Funded accounts Q4 2025 | C36: 3.85 | D36: m | E36: Q4_25 | F36: https://investors.etoro.com/news-releases (quarterly results; via search summaries) | G36: CO | H36: FY25 press said 3.81m; Q4 release 3.85m (conflict)
A37: FA_Q1_26 | B37: Funded accounts Q1 2026 | C37: 4.02 | D37: m | E37: Q1_26 | F37: https://investors.etoro.com/news-releases (quarterly results; via search summaries) | G37: CO
A38: FA_Q2_26 | B38: Funded accounts Q2 2026 | C38: 4.28 | D38: m | E38: Q2_26 | F38: https://investors.etoro.com/news-releases (quarterly results; via search summaries) | G38: CO
A39: AUA_Q2_25 | B39: AUA Q2 2025 | C39: 17.5 | D39: $bn | E39: Q2_25 | F39: https://investors.etoro.com/news-releases (quarterly results; via search summaries) | G39: CO/AGG
A40: AUA_Q3_25 | B40: AUA Q3 2025 | C40: 20.8 | D40: $bn | E40: Q3_25 | F40: https://investors.etoro.com/news-releases (quarterly results; via search summaries) | G40: CO/AGG | H40: Q3 25 via stocktwits recap (AGG)
A41: AUA_Q4_25 | B41: AUA Q4 2025 | C41: 18.5 | D41: $bn | E41: Q4_25 | F41: https://investors.etoro.com/news-releases (quarterly results; via search summaries) | G41: CO/AGG
A42: AUA_Q1_26 | B42: AUA Q1 2026 | C42: 18.7 | D42: $bn | E42: Q1_26 | F42: https://investors.etoro.com/news-releases (quarterly results; via search summaries) | G42: CO/AGG
A43: AUA_Q2_26 | B43: AUA Q2 2026 | C43: 19.2 | D43: $bn | E43: Q2_26 | F43: https://investors.etoro.com/news-releases (quarterly results; via search summaries) | G43: CO/AGG
A44: AUA_Aug26 | B44: AUA August 2026 | C44: 20.2 | D44: $bn | E44: Aug-26 | F44: https://www.manilatimes.net/2026/09/14/tmt-newswire/globenewswire/etoro-reports-selected-august-business-metrics/2424521 | G44: CO | H44: +3% YoY
A45: FA_Aug26 | B45: Funded accounts August 2026 | C45: 4.28 | D45: m | E45: Aug-26 | F45: same | G45: CO | H45: Identical to 30 Jun figure: possible stale repeat
A46: eToro: annual (US$m)
A47: NC_2023 | B47: Net contribution 2023 (LOW CONFIDENCE: 'revenue (total fees)') | C47: 639 | D47: $m | E47: FY23 | F47: https://www.calcalistech.com/ctechnews/article/sj6ykcjakg | G47: PR
A48: NC_2024 | B48: Net contribution 2024 | C48: 788 | D48: $m | E48: FY24 | F48: https://www.nasdaq.com/press-release/etoro-reports-fourth-quarter-and-full-year-2025-results-2026-02-17 | G48: CO
A49: NC_2025 | B49: Net contribution 2025 | C49: 868 | D49: $m | E49: FY25 | F49: https://www.financemagnates.com/fintech/etoro-reports-868m-net-contribution-for-2025-funded-accounts-rise-to-38-million/ | G49: CO
A50: EB_2023 | B50: Adj. EBITDA 2023 | C50: 117 | D50: $m | E50: FY23 | F50: https://www.calcalistech.com/ctechnews/article/sj6ykcjakg | G50: PR
A51: EB_2024 | B51: Adj. EBITDA 2024 | C51: 304 | D51: $m | E51: FY24 | F51: https://www.nasdaq.com/press-release/etoro-reports-fourth-quarter-and-full-year-2025-results-2026-02-17 | G51: CO
...

Sheet Historical Build & Ratios
A1: Historical build & ratios: eToro (US$m). All formulas; green = link to Inputs. Derived quarters are marked.
A3: Quarterly | B3: Q1 24 | C3: Q2 24 | D3: Q3 24 | E3: Q4 24 | F3: Q1 25 | G3: Q2 25 | H3: Q3 25 | I3: Q4 25 | J3: Q1 26 | K3: Q2 26 | M3: Note
A4: Net contribution ($m) | B4: =Inputs!$C$5 -> 201 | C4: =Inputs!$C$48-Inputs!$C$5-Inputs!$C$6-Inputs!$C$7 -> 167 | D4: =Inputs!$C$6 -> 167 | E4: =Inputs!$C$7 -> 253 | F4: =Inputs!$C$8 -> 217 | G4: =Inputs!$C$9 -> 210 | H4: =Inputs!$C$10 -> 215 | I4: =Inputs!$C$11 -> 227 | J4: =Inputs!$C$12 -> 258 | K4: =Inputs!$C$13 -> 229 | M4: Q2 24 derived = FY24 less Q1, Q3, Q4
A5: Adj. EBITDA ($m) | B5: =Inputs!$C$14 -> 87 | C5: =Inputs!$C$15 -> 55 | D5: =Inputs!$C$16 -> 55 | E5: =Inputs!$C$17 -> 108 | F5: =Inputs!$C$18 -> 80 | G5: =Inputs!$C$19 -> 72 | H5: =Inputs!$C$20 -> 78 | I5: =Inputs!$C$52-Inputs!$C$18-Inputs!$C$19-Inputs!$C$20 -> 87 | J5: =Inputs!$C$21 -> 109 | K5: =Inputs!$C$22 -> 78 | M5: Q4 25 derived = FY25 less Q1-Q3
A6: GAAP net income ($m) | B6: =Inputs!$C$23 -> 64 | C6: =Inputs!$C$24 -> 30.6 | D6: =Inputs!$C$25 -> 39 | E6: =Inputs!$C$26 -> 59 | F6: =Inputs!$C$27 -> 60 | G6: =Inputs!$C$28 -> 30.2 | H6: =Inputs!$C$29 -> 57 | I6: =Inputs!$C$55-Inputs!$C$27-Inputs!$C$28-Inputs!$C$29 -> 68.8 | J6: =Inputs!$C$30 -> 82 | K6: =Inputs!$C$31 -> 53 | M6: Q4 25 derived = FY25 less Q1-Q3
A7: Funded accounts (m) | D7: =Inputs!$C$32 -> 3.21 | F7: =Inputs!$C$33 -> 3.58 | G7: =Inputs!$C$34 -> 3.63 | H7: =Inputs!$C$35 -> 3.73 | I7: =Inputs!$C$36 -> 3.85 | J7: =Inputs!$C$37 -> 4.02 | K7: =Inputs!$C$38 -> 4.28 | M7: Blank = N/D
A8: AUA ($bn) | G8: =Inputs!$C$39 -> 17.5 | H8: =Inputs!$C$40 -> 20.8 | I8: =Inputs!$C$41 -> 18.5 | J8: =Inputs!$C$42 -> 18.7 | K8: =Inputs!$C$43 -> 19.2 | M8: Blank = N/D; Q3 25 via aggregator
A10: NC YoY growth | F10: =F4/B4-1 -> 0.07960199 | G10: =G4/C4-1 -> 0.25748503 | H10: =H4/D4-1 -> 0.28742515 | I10: =I4/E4-1 -> -0.1027668 | J10: =J4/F4-1 -> 0.18894009 | K10: =K4/G4-1 -> 0.09047619
A11: Adj. EBITDA YoY growth | F11: =F5/B5-1 -> -0.08045977 | G11: =G5/C5-1 -> 0.30909091 | H11: =H5/D5-1 -> 0.41818182 | I11: =I5/E5-1 -> -0.19444444 | J11: =J5/F5-1 -> 0.3625 | K11: =K5/G5-1 -> 0.083333333
A12: Net income YoY growth | F12: =F6/B6-1 -> -0.0625 | G12: =G6/C6-1 -> -0.013071895 | H12: =H6/D6-1 -> 0.46153846 | I12: =I6/E6-1 -> 0.16610169 | J12: =J6/F6-1 -> 0.36666667 | K12: =K6/G6-1 -> 0.75496689
A13: Adj. EBITDA margin (on NC) | B13: =B5/B4 -> 0.43283582 | C13: =C5/C4 -> 0.32934132 | D13: =D5/D4 -> 0.32934132 | E13: =E5/E4 -> 0.42687747 | F13: =F5/F4 -> 0.36866359 | G13: =G5/G4 -> 0.34285714 | H13: =H5/H4 -> 0.3627907 | I13: =I5/I4 -> 0.38325991 | ... K13: =K5/K4 -> 0.34061135
A14: Net margin (NI / NC) | B14: =B6/B4 -> 0.31840796 | C14: =C6/C4 -> 0.18323353 | D14: =D6/D4 -> 0.23353293 | E14: =E6/E4 -> 0.23320158 | F14: =F6/F4 -> 0.2764977 | G14: =G6/G4 -> 0.14380952 | H14: =H6/H4 -> 0.26511628 | I14: =I6/I4 -> 0.3030837 | ... K14: =K6/K4 -> 0.23144105
A15: Profitable quarter (1 = NI > 0) | B15: =IF(B6>0,1,0) -> 1 | C15: =IF(C6>0,1,0) -> 1 | D15: =IF(D6>0,1,0) -> 1 | E15: =IF(E6>0,1,0) -> 1 | F15: =IF(F6>0,1,0) -> 1 | G15: =IF(G6>0,1,0) -> 1 | H15: =IF(H6>0,1,0) -> 1 | I15: =IF(I6>0,1,0) -> 1 | ... K15: =IF(K6>0,1,0) -> 1
A16: Take-rate: annualised NC / AUA | B16: =IF(ISNUMBER(B8),B4*4/(B8*1000),"N/D") -> N/D | C16: =IF(ISNUMBER(C8),C4*4/(C8*1000),"N/D") -> N/D | D16: =IF(ISNUMBER(D8),D4*4/(D8*1000),"N/D") -> N/D | E16: =IF(ISNUMBER(E8),E4*4/(E8*1000),"N/D") -> N/D | F16: =IF(ISNUMBER(F8),F4*4/(F8*1000),"N/D") -> N/D | G16: =IF(ISNUMBER(G8),G4*4/(G8*1000),"N/D") -> 0.048 | H16: =IF(ISNUMBER(H8),H4*4/(H8*1000),"N/D") -> 0.041346154 | I16: =IF(ISNUMBER(I8),I4*4/(I8*1000),"N/D") -> 0.049081081 | ... K16: =IF(ISNUMBER(K8),K4*4/(K8*1000),"N/D") -> 0.047708333 | M16: Uses period-end AUA (not average)
A17: Annualised NC per funded account ($) | B17: =IF(ISNUMBER(B7),B4*4/B7,"N/D") -> N/D | C17: =IF(ISNUMBER(C7),C4*4/C7,"N/D") -> N/D | D17: =IF(ISNUMBER(D7),D4*4/D7,"N/D") -> 208.09969 | E17: =IF(ISNUMBER(E7),E4*4/E7,"N/D") -> N/D | F17: =IF(ISNUMBER(F7),F4*4/F7,"N/D") -> 242.4581 | G17: =IF(ISNUMBER(G7),G4*4/G7,"N/D") -> 231.40496 | H17: =IF(ISNUMBER(H7),H4*4/H7,"N/D") -> 230.563 | I17: =IF(ISNUMBER(I7),I4*4/I7,"N/D") -> 235.84416 | ... K17: =IF(ISNUMBER(K7),K4*4/K7,"N/D") -> 214.01869
A18: Funded accounts YoY growth | F18: =IF(AND(ISNUMBER(F7),ISNUMBER(B7)),F7/B7-1,"N/D") -> N/D | G18: =IF(AND(ISNUMBER(G7),ISNUMBER(C7)),G7/C7-1,"N/D") -> N/D | H18: =IF(AND(ISNUMBER(H7),ISNUMBER(D7)),H7/D7-1,"N/D") -> 0.16199377 | I18: =IF(AND(ISNUMBER(I7),ISNUMBER(E7)),I7/E7-1,"N/D") -> N/D | J18: =IF(AND(ISNUMBER(J7),ISNUMBER(F7)),J7/F7-1,"N/D") -> 0.12290503 | K18: =IF(AND(ISNUMBER(K7),ISNUMBER(G7)),K7/G7-1,"N/D") -> 0.17906336
A21: Annual / LTM | B21: FY23 | C21: FY24 | D21: FY25 | E21: LTM Q2 26 | F21: Prior LTM Q2 25 | G21: H1 25 | H21: H1 26 | M21: Note
A22: Net contribution ($m) | B22: =Inputs!$C$47 -> 639 | C22: =Inputs!$C$48 -> 788 | D22: =Inputs!$C$49 -> 868 | E22: =SUM(H4:K4) -> 929 | F22: =SUM(D4:G4) -> 847 | G22: =SUM(F4:G4) -> 427 | H22: =SUM(J4:K4) -> 487
A23: Adj. EBITDA ($m) | B23: =Inputs!$C$50 -> 117 | C23: =Inputs!$C$51 -> 304 | D23: =Inputs!$C$52 -> 317 | E23: =SUM(H5:K5) -> 352 | F23: =SUM(D5:G5) -> 315 | G23: =SUM(F5:G5) -> 152 | H23: =SUM(J5:K5) -> 187
A24: GAAP net income ($m) | B24: =Inputs!$C$53 -> 15.3 | C24: =Inputs!$C$54 -> 192 | D24: =Inputs!$C$55 -> 216 | E24: =SUM(H6:K6) -> 260.8 | F24: =SUM(D6:G6) -> 188.2 | G24: =SUM(F6:G6) -> 90.2 | H24: =SUM(J6:K6) -> 135
A25: YoY growth | C25: =C22/B22-1 -> 0.23317684 | D25: =D22/C22-1 -> 0.10152284 | E25: =E22/F22-1 -> 0.096812279 | H25: =H22/G22-1 -> 0.14051522
A26: Adj. EBITDA margin | B26: =B23/B22 -> 0.18309859 | C26: =C23/C22 -> 0.3857868 | D26: =D23/D22 -> 0.36520737 | E26: =E23/E22 -> 0.37890205 | F26: =F23/F22 -> 0.37190083 | G26: =G23/G22 -> 0.3559719 | H26: =H23/H22 -> 0.38398357
A27: Net margin | B27: =B24/B22 -> 0.023943662 | C27: =C24/C22 -> 0.24365482 | D27: =D24/D22 -> 0.24884793 | E27: =E24/E22 -> 0.28073197 | F27: =F24/F22 -> 0.22219599 | G27: =G24/G22 -> 0.21124122 | H27: =H24/H22 -> 0.27720739
A28: NC CAGR FY23-FY25 | B28: =(D22/B22)^(1/2)-1 -> 0.16549237
A29: Adj. EBITDA CAGR FY23-FY25 | B29: =(D23/B23)^(1/2)-1 -> 0.64602604
A30: NC CAGR FY24-LTM (1.5 yrs) | B30: =(E22/C22)^(1/1.5)-1 -> 0.11598836
A31: LTM NI growth | B31: =E24/F24-1 -> 0.38575983
A32: LTM adj. EBITDA growth | B32: =E23/F23-1 -> 0.11746032
A33: STDEVP adj. EBITDA margin, 10 qtrs | B33: =STDEVP(B13:K13) -> 0.038628111
A34: STDEVP adj. EBITDA margin, last 5 qtrs | B34: =STDEVP(G13:K13) -> 0.030270918
A35: Profitable quarters / disclosed quarters | B35: =SUM(B15:K15) -> 10 | C35: =COUNT(B6:K6) -> 10 | D35: =B35/C35 -> 1
A36: Cumulative GAAP NI FY23 to H1 26 ($m) | B36: =B24+C24+D24+H24 -> 558.3
A37: Total revenues & income growth Q2 26 | B37: =Inputs!$C$77/Inputs!$C$78-1 -> -0.23925501
A38: Crypto gross revenue growth Q2 26 | B38: =Inputs!$C$79/Inputs!$C$80-1 -> -0.29319372
A39: Sum of Q2 26 NC components ($m) | B39: =Inputs!$C$81+Inputs!$C$82+Inputs!$C$83+Inputs!$C$84 -> 228
A40: Capital-markets share of Q2 26 NC | B40: =Inputs!$C$81/K4 -> 0.62008734
A41: Net interest income share of Q2 26 NC | B41: =Inputs!$C$83/K4 -> 0.2139738
A45: Cross-check (recomputed vs stated) | B45: Recomputed | C45: Stated | D45: Diff | E45: Tolerance | F45: Result | M45: Tolerance 2pp on growth/margins because inputs are rounded to $1m in the summaries
A46: NC growth FY25 | B46: =D25 -> 0.10152284 | C46: =Inputs!$C$57 -> 0.1 | D46: =B46-C46 -> 0.0015228426 | E46: =Inputs!$C$190 -> 0.02 | F46: =IF(ABS(D46)<=E46,"MATCH","FLAG") -> MATCH
A47: NI growth FY25 | B47: =D24/C24-1 -> 0.125 | C47: =Inputs!$C$58 -> 0.12 | D47: =B47-C47 -> 0.005 | E47: =Inputs!$C$190 -> 0.02 | F47: =IF(ABS(D47)<=E47,"MATCH","FLAG") -> MATCH
...

Sheet Peer Benchmark
A1: Peer benchmark (US$m unless stated). Revenue basis: eToro = net contribution; peers = total revenue / net revenue / operating income as labelled.
A3: Company | B3: Scale metric | C3: Scale (m) | D3: Client assets ($bn) | E3: Revenue basis | F3: Revenue ($m) | G3: Profit basis | H3: Profit ($m) | I3: Net income basis ($m) | J3: Market cap ($m) | K3: Corporate cash credited ($m) | L3: EV ($m) | M3: EV / Revenue (x) | N3: Mcap / Revenue (x) | O3: P/E (x) | P3: Revenue growth (latest) | Q3: EV/Rev per pt of growth | R3: Data quality
A4: eToro (base: 79.53m sh; 50% cash credit) | B4: Funded accounts | C4: ='Historical Build & Ratios'!K7 -> 4.28 | D4: ='Historical Build & Ratios'!K8 -> 19.2 | E4: LTM net contribution | F4: ='Historical Build & Ratios'!E22 -> 929 | G4: LTM adj. EBITDA | H4: ='Historical Build & Ratios'!E23 -> 352 | I4: ='Historical Build & Ratios'!E24 -> 260.8 | J4: =Inputs!$C$88*Inputs!$C$89 -> 2099.592 | K4: =Inputs!$C$93*Inputs!$C$188-Inputs!$C$94 -> 600 | L4: =IF(ISNUMBER(K4),J4-K4,J4) -> 1499.592 | M4: =IF(ISNUMBER(L4),L4/F4,"N/D") -> 1.6142002 | N4: =IF(ISNUMBER(J4),J4/F4,"N/D") -> 2.260056 | O4: =IF(AND(ISNUMBER(J4),ISNUMBER(I4)),J4/I4,"N/D") -> 8.0505828 | P4: ='Historical Build & Ratios'!H25 -> 0.14051522 | Q4: =IF(AND(ISNUMBER(M4),ISNUMBER(P4)),IF(P4>0,M4/(P4*100),"n.m."),"N/D") -> 0.11487725 | R4: Listed/audited (search-summary basis); Q2 26 funded acct = 30 Jun
A5: IG Group (CONFLICT: requester's employer) | B5: Active customers | C5: =Inputs!$C$123 -> 0.8436 | D5: =Inputs!$C$124*Inputs!$C$110 -> 28.47675 | E5: LTM total revenue | F5: =(Inputs!$C$116+Inputs!$C$115-Inputs!$C$116/(1+Inputs!$C$117))*Inputs!$C$110 -> 1617.8161 | G5: CY25 EBITDA | H5: =Inputs!$C$118*Inputs!$C$110 -> 703.44195 | I5: N/D | J5: =Inputs!$C$122*Inputs!$C$110 -> 5841.045 | K5: N/D | L5: =IF(ISNUMBER(K5),J5-K5,J5) -> 5841.045 | M5: =IF(ISNUMBER(L5),L5/F5,"N/D") -> 3.6104504 | N5: =IF(ISNUMBER(J5),J5/F5,"N/D") -> 3.6104504 | O5: =Inputs!$C$121/Inputs!$C$120 -> 11.603816 | P5: =Inputs!$C$117 -> 0.18 | Q5: =IF(AND(ISNUMBER(M5),ISNUMBER(P5)),IF(P5>0,M5/(P5*100),"n.m."),"N/D") -> 0.20058058 | R5: Listed/audited; H1 25 derived from stated growth; P/E on adj EPS
A6: Plus500 | B6: Active customers | C6: =Inputs!$C$134 -> 0.197 | D6: =Inputs!$C$135 -> 3.4 | E6: LTM revenue | F6: =Inputs!$C$126+Inputs!$C$125-Inputs!$C$126/(1+Inputs!$C$127) -> 841.60714 | G6: LTM EBITDA | H6: =Inputs!$C$129+Inputs!$C$128-Inputs!$C$129/(1+Inputs!$C$130) -> 349.85644 | I6: =Inputs!$C$131 -> 281.3 | J6: =Inputs!$C$132*Inputs!$C$110 -> 3337.74 | K6: =Inputs!$C$133 -> 800 | L6: =IF(ISNUMBER(K6),J6-K6,J6) -> 2537.74 | M6: =IF(ISNUMBER(L6),L6/F6,"N/D") -> 3.0153499 | N6: =IF(ISNUMBER(J6),J6/F6,"N/D") -> 3.9659122 | O6: =IF(AND(ISNUMBER(J6),ISNUMBER(I6)),J6/I6,"N/D") -> 11.865411 | P6: =Inputs!$C$127 -> 0.12 | Q6: =IF(AND(ISNUMBER(M6),ISNUMBER(P6)),IF(P6>0,M6/(P6*100),"n.m."),"N/D") -> 0.25127916 | R6: Listed/audited; NI = FY25; cash at YE25
A7: Webull | B7: Funded accounts | C7: =Inputs!$C$144 -> 5.13 | D7: =Inputs!$C$145 -> 28.5 | E7: LTM revenue | F7: =Inputs!$C$136-Inputs!$C$138-Inputs!$C$139/(1+Inputs!$C$140)+Inputs!$C$137+Inputs!$C$139 -> 680.64437 | G7: Q2 26 adj. op profit x4 | H7: =Inputs!$C$141*4 -> 250.4 | I7: N/D | J7: =Inputs!$C$143 -> 4380 | K7: N/D | L7: =IF(ISNUMBER(K7),J7-K7,J7) -> 4380 | M7: =IF(ISNUMBER(L7),L7/F7,"N/D") -> 6.4350786 | N7: =IF(ISNUMBER(J7),J7/F7,"N/D") -> 6.4350786 | O7: =IF(AND(ISNUMBER(J7),ISNUMBER(I7)),J7/I7,"N/D") -> N/D | P7: =(Inputs!$C$137+Inputs!$C$139)/(Inputs!$C$138+Inputs!$C$139/(1+Inputs!$C$140))-1 -> 0.44024048 | Q7: =IF(AND(ISNUMBER(M7),ISNUMBER(P7)),IF(P7>0,M7/(P7*100),"n.m."),"N/D") -> 0.14617189 | R7: Listed/audited; Q2 25 derived; LTM GAAP NI N/D
A8: XTB | B8: Active clients | C8: =Inputs!$C$154 -> 1.49 | D8: N/D | E8: LTM total operating income | F8: =(Inputs!$C$147+Inputs!$C$146-Inputs!$C$147/(1+Inputs!$C$148))*Inputs!$C$113 -> 828.67289 | G8: H1 26 EBITDA x2 | H8: =Inputs!$C$152*2*Inputs!$C$113 -> 655.32672 | I8: =(Inputs!$C$150+Inputs!$C$149-Inputs!$C$150/(1+Inputs!$C$151))*Inputs!$C$113 -> 339.77292 | J8: =Inputs!$C$153*Inputs!$C$113 -> 4947.2856 | K8: N/D | L8: =IF(ISNUMBER(K8),J8-K8,J8) -> 4947.2856 | M8: =IF(ISNUMBER(L8),L8/F8,"N/D") -> 5.9701309 | N8: =IF(ISNUMBER(J8),J8/F8,"N/D") -> 5.9701309 | O8: =IF(AND(ISNUMBER(J8),ISNUMBER(I8)),J8/I8,"N/D") -> 14.560565 | P8: =Inputs!$C$148 -> 0.797 | Q8: =IF(AND(ISNUMBER(M8),ISNUMBER(P8)),IF(P8>0,M8/(P8*100),"n.m."),"N/D") -> 0.074907539 | R8: Listed/audited; H1 25 derived; EBITDA annualised from one half
A9: Trading 212 (private) | B9: Funded accounts (group, self-rep.) | C9: =Inputs!$C$160 -> 4.5 | D9: =Inputs!$C$161*Inputs!$C$110 -> 43.033005 | E9: FY25 revenue (UK Ltd) | F9: =Inputs!$C$156*Inputs!$C$110 -> 367.6812 | G9: FY25 PBT (UK Ltd) | H9: =Inputs!$C$158*Inputs!$C$110 -> 163.04595 | I9: =Inputs!$C$159*Inputs!$C$110 -> 122.1189 | J9: N/D | K9: N/D | L9: N/D | M9: =IF(ISNUMBER(L9),L9/F9,"N/D") -> N/D | N9: =IF(ISNUMBER(J9),J9/F9,"N/D") -> N/D | O9: =IF(AND(ISNUMBER(J9),ISNUMBER(I9)),J9/I9,"N/D") -> N/D | P9: =Inputs!$C$156/Inputs!$C$157-1 -> 0.71675943 | Q9: =IF(AND(ISNUMBER(M9),ISNUMBER(P9)),IF(P9>0,M9/(P9*100),"n.m."),"N/D") -> N/D | R9: Private: UK entity audited (Companies House); group metrics self-reported; no valuation marker
A10: Swissquote | B10: Accounts | C10: =Inputs!$C$170 -> 1.2 | D10: =Inputs!$C$171/Inputs!$C$112 -> 116.27767 | E10: LTM net revenues | F10: =(Inputs!$C$162-Inputs!$C$163+Inputs!$C$164)/Inputs!$C$112 -> 880.83652 | G10: LTM PBT | H10: =(Inputs!$C$165-Inputs!$C$166+Inputs!$C$167)/Inputs!$C$112 -> 502.05871 | I10: N/D | J10: =Inputs!$C$168*Inputs!$C$169/Inputs!$C$112 -> 6692.3803 | K10: N/D | L10: =IF(ISNUMBER(K10),J10-K10,J10) -> 6692.3803 | M10: =IF(ISNUMBER(L10),L10/F10,"N/D") -> 7.5977552 | N10: =IF(ISNUMBER(J10),J10/F10,"N/D") -> 7.5977552 | O10: =IF(AND(ISNUMBER(J10),ISNUMBER(I10)),J10/I10,"N/D") -> N/D | P10: =Inputs!$C$164/Inputs!$C$163-1 -> 0.017318436 | Q10: =IF(AND(ISNUMBER(M10),ISNUMBER(P10)),IF(P10>0,M10/(P10*100),"n.m."),"N/D") -> 4.3870909 | R10: Listed/audited; price x 149.88m shares reconciles to quoted cap
A12: Note: eToro revenue = net contribution (net of crypto cost of sales). Gross 'total revenues & income' ($13.8bn FY25) is not comparable. Its growth rate is shown in cols P/Q.
A13: eToro growth in col P = H1 26 vs H1 25 net contribution. IG and Plus500 = H1 26 growth; Webull = H1 26 vs H1 25; XTB = H1 26; Trading 212 = FY25; Swissquote = H1 26.
A14: Rank on scale (funded/active accounts, m): 1 = largest. eToro rank: | F14: =RANK(C4,C4:C10) -> 3
A15: Rank on revenue ($m), eToro: | F15: =RANK(F4,F4:F10) -> 2
A16: Rank on client assets ($bn, of those disclosed), eToro: | F16: =RANK(D4,D4:D10) -> 5
A17: Peer median EV/Revenue or Mcap/Revenue (listed peers ex-eToro) | F17: =MEDIAN(N5:N8,N10) -> 5.9701309
A18: Peer median P/E (IG, Plus500, XTB) | F18: =MEDIAN(O5,O6,O8) -> 11.865411
A19: Plus500 EV / LTM EBITDA (closest listed peer) | F19: =L6/H6 -> 7.253661
A20: IG Mcap / CY25 EBITDA (no cash adj.) | F20: =J5/H5 -> 8.303521
A23: Moat ratings (analyst inputs; Strong / Moderate / Weak) | B23: Network effects | C23: Switching costs | D23: Scale / cost | E23: Intangible / regulatory | F23: # Strong | G23: # Moderate | H23: Evidence basis
A24: eToro | B24: Moderate | C24: Weak | D24: Moderate | E24: Moderate | F24: =COUNTIF(B24:E24,"Strong") -> 0 | G24: =COUNTIF(B24:E24,"Moderate") -> 3 | H24: CopyTrader/Popular Investor social graph (self-reported); multi-licence incl. MiCA, ASIC, FCA; no tax-wrapper lock-in at scale
A25: IG Group | B25: Weak | C25: Moderate | D25: Moderate | E25: Moderate | F25: =COUNTIF(B25:E25,"Strong") -> 0 | G25: =COUNTIF(B25:E25,"Moderate") -> 3 | H25: ISA/SIPP via Freetrade; long-established brand (founded 1974); audited
A26: Plus500 | B26: Weak | C26: Weak | D26: Moderate | E26: Moderate | F26: =COUNTIF(B26:E26,"Strong") -> 0 | G26: =COUNTIF(B26:E26,"Moderate") -> 2 | H26: Proprietary tech, 41% EBITDA margin; US futures business (non-OTC >$100m revenue FY25); audited
A27: Webull | B27: Weak | C27: Weak | D27: Moderate | E27: Moderate | F27: =COUNTIF(B27:E27,"Strong") -> 0 | G27: =COUNTIF(B27:E27,"Moderate") -> 2 | H27: US broker-dealer; EEA licence; audited
A28: XTB | B28: Weak | C28: Weak | D28: Moderate | E28: Moderate | F28: =COUNTIF(B28:E28,"Strong") -> 0 | G28: =COUNTIF(B28:E28,"Moderate") -> 2 | H28: Scale economics shown by 58% EBITDA margin H1 26; audited
A29: Trading 212 | B29: Weak | C29: Moderate | D29: Moderate | E29: Weak | F29: =COUNTIF(B29:E29,"Strong") -> 0 | G29: =COUNTIF(B29:E29,"Moderate") -> 2 | H29: ISA/SIPP wrappers in UK; low-cost model; group metrics self-reported
A30: Swissquote | B30: Weak | C30: Moderate | D30: Moderate | E30: Moderate | F30: =COUNTIF(B30:E30,"Strong") -> 0 | G30: =COUNTIF(B30:E30,"Moderate") -> 3 | H30: Swiss banking licence; custody franchise; audited
A32: Sector count of 'Strong' ratings (all firms, all categories) | F32: =SUM(F24:F30) -> 0

Sheet Valuation & Scenarios
A1: eToro valuation: EV range, M&A cross-checks, bull/base/bear (US$m unless stated)
A3: EV range: share count x cash credit | B3: Basic 79.53m | C3: Basic 82.85m (20-F) | D3: Diluted (NI/EPS) | F3: Note
A4: Shares (m) | B4: =Inputs!$C$89 -> 79.53 | C4: =Inputs!$C$90 -> 82.85 | D4: ='Historical Build & Ratios'!B78 -> 91.37931 | F4: 70.04m cover figure rejected (does not reconcile with 20-F Cl B)
A5: Market cap at $26.40 | B5: =B4*Inputs!$C$88 -> 2099.592 | C5: =C4*Inputs!$C$88 -> 2187.24 | D5: =D4*Inputs!$C$88 -> 2412.4138
A6: EV, case A: 100% cash credit | B6: =B$5-Inputs!$C$93*Inputs!$C$187+Inputs!$C$94 -> 899.592 | C6: =C$5-Inputs!$C$93*Inputs!$C$187+Inputs!$C$94 -> 987.24 | D6: =D$5-Inputs!$C$93*Inputs!$C$187+Inputs!$C$94 -> 1212.4138 | F6: Cash split corporate vs regulatory N/D; debt assumed nil
A7: EV, case B: 50% cash credit (central) | B7: =B$5-Inputs!$C$93*Inputs!$C$188+Inputs!$C$94 -> 1499.592 | C7: =C$5-Inputs!$C$93*Inputs!$C$188+Inputs!$C$94 -> 1587.24 | D7: =D$5-Inputs!$C$93*Inputs!$C$188+Inputs!$C$94 -> 1812.4138
A8: EV, case C: 0% cash credit | B8: =B$5-Inputs!$C$93*Inputs!$C$189+Inputs!$C$94 -> 2099.592 | C8: =C$5-Inputs!$C$93*Inputs!$C$189+Inputs!$C$94 -> 2187.24 | D8: =D$5-Inputs!$C$93*Inputs!$C$189+Inputs!$C$94 -> 2412.4138
A9: EV / LTM NC, case A | B9: =B6/'Historical Build & Ratios'!E22 -> 0.96834446 | C9: =C6/'Historical Build & Ratios'!E22 -> 1.0626911 | D9: =D6/'Historical Build & Ratios'!E22 -> 1.3050741
A10: EV / LTM NC, case B | B10: =B7/'Historical Build & Ratios'!E22 -> 1.6142002 | C10: =C7/'Historical Build & Ratios'!E22 -> 1.7085468 | D10: =D7/'Historical Build & Ratios'!E22 -> 1.9509298
A11: EV / LTM NC, case C | B11: =B8/'Historical Build & Ratios'!E22 -> 2.260056 | C11: =C8/'Historical Build & Ratios'!E22 -> 2.3544026 | D11: =D8/'Historical Build & Ratios'!E22 -> 2.5967856
A12: EV / LTM adj. EBITDA, case A | B12: =B6/'Historical Build & Ratios'!E23 -> 2.5556591 | C12: =C6/'Historical Build & Ratios'!E23 -> 2.8046591 | D12: =D6/'Historical Build & Ratios'!E23 -> 3.4443574
A13: EV / LTM adj. EBITDA, case B | B13: =B7/'Historical Build & Ratios'!E23 -> 4.2602045 | C13: =C7/'Historical Build & Ratios'!E23 -> 4.5092045 | D13: =D7/'Historical Build & Ratios'!E23 -> 5.1489028
A14: EV / LTM adj. EBITDA, case C | B14: =B8/'Historical Build & Ratios'!E23 -> 5.96475 | C14: =C8/'Historical Build & Ratios'!E23 -> 6.21375 | D14: =D8/'Historical Build & Ratios'!E23 -> 6.8534483
A15: P/E on LTM GAAP NI | B15: =B5/'Historical Build & Ratios'!E24 -> 8.0505828 | C15: =C5/'Historical Build & Ratios'!E24 -> 8.3866564 | D15: =D5/'Historical Build & Ratios'!E24 -> 9.2500529
A16: EV per funded account ($), case B | B16: =B7/'Historical Build & Ratios'!K7 -> 350.37196 | C16: =C7/'Historical Build & Ratios'!K7 -> 370.85047 | D16: =D7/'Historical Build & Ratios'!K7 -> 423.46117
A17: Share price vs IPO price | B17: =Inputs!$C$88/Inputs!$C$95-1 -> -0.49230769
A18: Market cap vs 2023 round ($3.5bn) | B18: =B5/Inputs!$C$198-1 -> -0.40011657
A19: Market cap vs SPAC valuation | B19: =B5/Inputs!$C$99-1 -> -0.79811615
A21: Growth-adjusted and peer cross-check | B21: eToro (B, 79.53m) | C21: Plus500 | F21: Note
A22: EV / LTM revenue | B22: ='Peer Benchmark'!M4 -> 1.6142002 | C22: ='Peer Benchmark'!M6 -> 3.0153499
A23: EV / LTM EBITDA | B23: =B13 -> 4.2602045 | C23: ='Peer Benchmark'!F19 -> 7.253661
A24: Revenue growth (H1 26) | B24: ='Peer Benchmark'!P4 -> 0.14051522 | C24: ='Peer Benchmark'!P6 -> 0.12
A25: EV/Revenue / growth (pts) | B25: =B22/(B24*100) -> 0.11487725 | C25: =C22/(C24*100) -> 0.25127916
A26: EV/EBITDA / growth (pts) | B26: =B23/(B24*100) -> 0.30318456 | C26: =C23/(C24*100) -> 0.60447175
A27: eToro discount to Plus500 on EV/EBITDA | B27: =B23/C23-1 -> -0.41268216
A28: eToro case C (0% cash) EV/EBITDA vs Plus500 | B28: =B14/C23-1 -> -0.17769111
A29: P/E: eToro vs peer median (IG, Plus500, XTB) | B29: =B15 -> 8.0505828 | C29: ='Peer Benchmark'!F18 -> 11.865411
A31: M&A cross-checks | B31: Freetrade (IG) | C31: Saxo (JSS) | D31: TradeZero (eToro, pending) | E31: eToro today (B) | F31: Note
A32: Implied 100% value ($m) | B32: =Inputs!$C$174*Inputs!$C$110 -> 211.92 | C32: =Inputs!$C$179/Inputs!$C$180*Inputs!$C$111 -> 1846.3333 | D32: =Inputs!$C$102 -> 231 | E32: =B7 -> 1499.592
A33: Value / revenue (x) | B33: =Inputs!$C$174/Inputs!$C$175 -> 5.8181818 | C33: N/D | D33: =Inputs!$C$102/Inputs!$C$103 -> 2.8875 | E33: =B10 -> 1.6142002
A34: Value / net profit (x) | B34: n.m. | C34: =Inputs!$C$179/Inputs!$C$180/Inputs!$C$181 -> 13.425926 | D34: N/D | E34: =B15 -> 8.0505828
A35: Value per customer / funded account ($) | B35: =B32/Inputs!$C$176 -> 294.33333 | C35: =C32/Inputs!$C$182 -> 1230.8889 | D35: N/D | E35: =B16 -> 350.37196
A36: Value / client assets | B36: =Inputs!$C$174/Inputs!$C$177 -> 0.064 | C36: =C32/(Inputs!$C$183*Inputs!$C$111*1000) -> 0.012113617 | D36: N/D | E36: =B7/('Historical Build & Ratios'!K8*1000) -> 0.07810375 | F36: Share of client assets (%)
A37: eToro implied at Freetrade $/customer x 4.28m funded ($m) | B37: =B35*'Historical Build & Ratios'!K7 -> 1259.7467
A38: eToro implied at Saxo P/E x LTM NI ($m equity) | B38: =C34*'Historical Build & Ratios'!E24 -> 3501.4815
A39: TradeZero share consideration at today's price ($m) | B39: =Inputs!$C$104*Inputs!$C$88 -> 66
A40: TradeZero multiple vs eToro's own EV/NC (case B) | B40: =D33/B10 -> 1.7888116
A42: Scenarios (12-month forward from LTM Q2 26) | B42: Bear | C42: Base | D42: Bull | F42: Note
A43: LTM net contribution ($m) | B43: ='Historical Build & Ratios'!E22 -> 929 | C43: ='Historical Build & Ratios'!E22 -> 929 | D43: ='Historical Build & Ratios'!E22 -> 929
A44: NTM NC growth | B44: -0.1 | C44: 0.08 | D44: 0.15 | F44: Bear: crypto/volatility slump. Base: FY25-like growth. Bull: H1 26 pace sustained
...

Sheet Audit Log
A1: # | B1: Sheet!Ref | C1: Severity | D1: Category | E1: Issue | F1: Suggested fix
A2: 1 | B2: README!A15 | C2: Critical | D2: Data access | E2: WebFetch was blocked by the egress proxy for all primary sources (investors.etoro.com, sec.gov, globenewswire). Every figure comes from search-engine summaries of those URLs. | F2: Re-verify every blue input against the 20-F and 6-K filings before any external use.
A3: 2 | B3: Inputs!CASH_ETOR / Valuation & Scenarios!B6:D8 | C3: Critical | D3: Valuation | E3: The $1.2bn 'cash, cash equivalents & short-term investments' has no disclosed split between free corporate cash and regulatory capital. EV swings from $0.90bn to $2.10bn (base share count) on this alone. | F3: Obtain entity-level regulatory capital requirements from the 20-F / Pillar 3 disclosures. Until then, use the case B central view and show the range.
A4: 3 | B4: Inputs!SH_* / Valuation & Scenarios!B4:D4 | C4: Warning | D4: Capital structure | E4: Share count conflicts: 70.04m (Feb 26 cover), 82.85m (20-F YE25: 68.65m A + 14.20m B), 79.53m (aggregator), ~91.4m diluted (Q2 NI $53m / EPS $0.58). Market cap ranges $2.10bn to $2.41bn. | F4: Take the basic count from the Q2 26 6-K. The 70.04m figure is rejected because it cannot be reconciled to the 20-F Class B count.
A5: 4 | B5: Historical Build & Ratios!B37 | C5: Warning | D5: Reporting / definitions | E5: Three incompatible Q2 26 'revenue' growth rates circulate: NC +9%, total revenues & income -24%, and FX News Group's 'revenues fall 11%'. The -11% ties to neither. | F5: Use net contribution as the only comparable top line. Treat gross crypto revenue (94% of FY25 total revenues) as a pass-through.
A6: 5 | B6: Inputs!CRYPTO_Q2_25 | C6: Info | D6: Press error | E6: CoinDesk headline says crypto revenue 'dropped 120%'. That is impossible; the recomputed decline is -29%. | F6: Disregard the headline percentage.
A7: 6 | B7: Historical Build & Ratios!F72 | C7: Warning | D7: Internal inconsistency | E7: Q4 25 funded accounts are stated as 3.85m in the Q4 release and 3.81m in the FY25 press coverage. | F7: Confirm in the 20-F. The build uses 3.85m.
A8: 7 | B8: Inputs!FA_Aug26 | C8: Warning | D8: Unexplained flat-line | E8: August 2026 funded accounts (4.28m) are identical to 30 June. AUA growth slowed to +3% YoY in August from +10% in June. | F8: Check the monthly metrics release. Treat Q3 26 account growth as unproven.
A9: 8 | B9: Historical Build & Ratios!K11 | C9: Warning | D9: Unexplained inflection | E9: Adj. EBITDA growth fell from +35% (Q1 26) to +9% (Q2 26). Q1 was boosted by a ~4x surge in commodities volumes, and management plans to raise marketing to 25% of NC by YE26. | F9: Model margins at 33-38%, not at the Q1 peak.
A10: 9 | B10: Historical Build & Ratios!K12 | C10: Info | D10: Base effect | E10: Q2 26 NI growth of +77% flatters: the Q2 25 base ($30.2m) included $15m of IPO costs. On an ex-IPO-cost base, growth is ~+17%. | F10: Present NI growth ex one-offs.
A11: 10 | B11: Historical Build & Ratios!B4 / B22 | C11: Warning | D11: Derived data | E11: Q2 24 NC, Q4 25 adj EBITDA and Q4 25 NI are derived (FY less other quarters), not disclosed. FY23 NC ($639m) is described in the press as 'revenue (total fees)'. | F11: Replace with disclosed figures from the F-1 / 20-F.
A12: 11 | B12: Historical Build & Ratios!B13:K13 | C12: Info | D12: Non-statutory measures | E12: Adj. EBITDA and net contribution are non-GAAP. The GAAP equivalent of NC (total revenues & income) is dominated by gross crypto sales. | F12: Anchor profitability tests on GAAP NI where possible (done in the Scorecard).
A13: 12 | B13: Historical Build & Ratios!B40 | C13: Warning | D13: Cyclicality | E13: Earnings mix swings with retail activity: crypto went from 50% of trading commission (Q4 24) to 11% (Q2 26); commodities were 60% in Q1 26 and equities 60% in Q2 26. NII ($49m, 21% of NC) is rate-sensitive. | F13: Stress NC against a low-volatility, falling-rate scenario (bear case).
... A25: 24 | B25: Historical Build & Ratios!B16:K16 | C25: Info | D25: Model limitation | E25: The take-rate uses period-end AUA, not average AUA, and is only available for 5 quarters. | F25: Replace with average AUA from the filings.

Sheet Buffett Scorecard
A1: Earnings-durability scorecard: one investor's published framework (Warren Buffett's shareholder letters). Not a claim about what Buffett would conclude.
A3: # | B3: Test | C3: Metric | D3: Value | E3: Secondary value | F3: PASS / CAUTION thresholds | G3: Verdict | H3: Evidence / comment
A4: 1 | B4: Consistent operating history | C4: Profitable quarters / disclosed quarters (secondary = # quarters) | D4: ='Historical Build & Ratios'!D35 -> 1 | E4: ='Historical Build & Ratios'!C35 -> 10 | F4: PASS >= 90% over >= 12 qtrs; CAUTION if <12 qtrs; FAIL < 75% | G4: =IF(D4<0.75,"FAIL",IF(E4>=12,"PASS","CAUTION")) -> CAUTION | H4: Profitable in 10 of 10 disclosed quarters, but the disclosed history is short (FY23 NI only $15.3m; pre-2023 N/D; failed SPAC period).
A5: 2 | B5: Stable, predictable margins | C5: STDEVP adj. EBITDA margin: full 10 qtrs (secondary = last 5) | D5: ='Historical Build & Ratios'!B33 -> 0.038628111 | E5: ='Historical Build & Ratios'!B34 -> 0.030270918 | F5: PASS < 3pp; CAUTION 3-6pp; FAIL > 6pp (on the higher of the two) | G5: =IF(MAX(D5,E5)>0.06,"FAIL",IF(MAX(D5,E5)>0.03,"CAUTION","PASS")) -> CAUTION | H5: Margins ranged 33-43% on NC. Swings track retail volume regimes (crypto Q4 24, commodities Q1 26).
A6: 3 | B6: Self-funded growth | C6: Cumulative GAAP NI FY23-H1 26 / external capital raised since 2023 (2023 round + IPO primary) | D6: ='Historical Build & Ratios'!B36/(Inputs!$C$98+Inputs!$C$97) -> 0.99696429 | E6: =Inputs!$C$98+Inputs!$C$97 -> 560 | F6: PASS >= 1.5x; CAUTION 0.75-1.5x; FAIL < 0.75x | G6: =IF(D6>=1.5,"PASS",IF(D6>=0.75,"CAUTION","FAIL")) -> CAUTION | H6: Earnings since 2023 roughly equal the capital raised since 2023. Pre-2023 raises N/D. A $50m buyback in Feb 26 is a positive offset.
A7: 4 | B7: Organic compounding | C7: Upper-bound acquired share of funded-account growth, Q3 24-Q2 26 (Spaceship clients / account growth) | D7: =Inputs!$C$106/('Historical Build & Ratios'!K7-'Historical Build & Ratios'!D7) -> 0.18691589 | E7: ='Historical Build & Ratios'!K7-'Historical Build & Ratios'!D7 -> 1.07 | F7: PASS < 10%; CAUTION 10-30%; FAIL > 30% | G7: =IF(D7>0.3,"FAIL",IF(D7>0.1,"CAUTION","PASS")) -> CAUTION | H7: The Spaceship (AU) contribution is undisclosed, so an upper bound is used. TradeZero (pending) would add inorganic US accounts from H1 27.
A8: 5 | B8: Durable, behavioural moat | C8: # 'Strong' moat ratings for eToro (secondary = # Moderate) | D8: ='Peer Benchmark'!F24 -> 0 | E8: ='Peer Benchmark'!G24 -> 3 | F8: PASS >= 2 Strong; CAUTION 1 Strong or >= 2 Moderate; else FAIL | G8: =IF(D8>=2,"PASS",IF(OR(D8=1,E8>=2),"CAUTION","FAIL")) -> CAUTION | H8: No Strong rating for eToro, or for anyone in the sector. The social/copy network effect rests on self-reported engagement data.
A9: 6 | B9: Rational, aligned management | C9: CEO voting power (secondary = # reversed decisions) | D9: =Inputs!$C$101 -> 0.0934 | E9: =Inputs!$C$108 -> 1 | F9: PASS >= 10% and 0 reversals; CAUTION >= 5%; else FAIL | G9: =IF(AND(D9>=0.1,E9=0),"PASS",IF(D9>=0.05,"CAUTION","FAIL")) -> CAUTION | H9: Founder CEO holds 9.3% of votes. SPAC at $10.4bn abandoned in 2022. Buyback at ~$30 then share-funded TradeZero at 2.9x revenue, above eToro's own multiple.
A10: 7 | B10: Simple, predictable business | C10: Count of concurrent forward initiatives | D10: =Inputs!$C$107 -> 8 | F10: PASS <= 3; CAUTION 4-5; FAIL >= 6 | G10: =IF(D10>=6,"FAIL",IF(D10>=4,"CAUTION","PASS")) -> FAIL | H10: TradeZero/US; app migration; tokenisation/24-5; futures & US commodities; marketing ramp; eToro Money; AI agents; ASIC litigation.
A11: 8 | B11: Wonderful company at a fair price | C11: EV/LTM adj. EBITDA, case B, vs Plus500 (secondary = case C, 0% cash) | D11: ='Valuation & Scenarios'!B13/'Valuation & Scenarios'!C23 -> 0.58731784 | E11: ='Valuation & Scenarios'!B14/'Valuation & Scenarios'!C23 -> 0.82230889 | F11: PASS < 0.8x of peer; CAUTION 0.8-1.1x; FAIL > 1.1x | G11: =IF(D11<0.8,"PASS",IF(D11<=1.1,"CAUTION","FAIL")) -> PASS | H11: Price test passes even with zero cash credit, but on the growth-adjusted view the discount is smaller. It is a fair price for a cyclical business, not proof of a wonderful company.
B13: Tally | C13: PASS | D13: =COUNTIF(G4:G11,"PASS") -> 1
C14: CAUTION | D14: =COUNTIF(G4:G11,"CAUTION") -> 6
C15: FAIL | D15: =COUNTIF(G4:G11,"FAIL") -> 1
